<?xml version="1.0" ?>
<!-- =================================================================================== -->
<!-- |    This document was autogenerated by xacro from /home/vinayaka/ros_ws/src/ur_description/urdf/ur10_robot.urdf.xacro | -->
<!-- |    EDITING THIS FILE BY HAND IS NOT RECOMMENDED                                 | -->
<!-- =================================================================================== -->
<robot name="ur10">
    <!-- measured from model -->
    <link name="base_link">
        <visual>
            <geometry>
                <mesh filename="package://ur_description/meshes/ur10/visual/base.dae" />
            </geometry>
        </visual>
        <inertial>
            <mass value="4.0" />
            <origin rpy="0 0 0" xyz="0.0 0.0 0.0" />
            <inertia ixx="0.0061063308908" ixy="0.0" ixz="0.0" iyy="0.0061063308908" iyz="0.0" izz="0.01125" />
        </inertial>
    </link>
    <joint name="shoulder_pan_joint" type="revolute">
        <parent link="base_link" />
        <child link="shoulder_link" />
        <origin rpy="0.0 0.0 0.0" xyz="0.0 0.0 0.1273" />
        <axis xyz="0 0 1" />
        <limit effort="330.0" lower="-3.1" upper="3.1" velocity="2.16" />
        <dynamics damping="0.0" friction="0.0" />
    </joint>
    <link name="shoulder_link">
        <visual>
            <geometry>
                <mesh filename="package://ur_description/meshes/ur10/visual/shoulder.dae" />
            </geometry>
        </visual>
        <collision>
            <origin rpy="0 0 0" xyz="0 0 0.0" />
            <geometry>
                <sphere radius="0.11" />
            </geometry>
        </collision>
        <inertial>
            <mass value="7.778" />
            <origin rpy="0 0 0" xyz="0.0 0.0 0.0" />
            <inertia ixx="0.03147431257693659" ixy="0.0" ixz="0.0" iyy="0.03147431257693659" iyz="0.0" izz="0.021875624999999996" />
        </inertial>
    </link>
    <link name="rounded_tip_link">
        <inertial>
            <origin rpy="0 0 0" xyz="0 0 0.055" />
            <mass value="0.1" />
            <inertia ixx="1e-4" ixy="0" ixz="0" iyy="1e-4" iyz="0" izz="1e-4" />
        </inertial>
        <!-- Visual: cylinder shaft -->
        <visual>
            <!-- Cylinder base at link origin, pointing +Z -->
            <origin rpy="0 0 0" xyz="0 0 0" />
            <geometry>
                <cylinder length="0.10" radius="0.01" />
            </geometry>
            <material name="gray">
                <color rgba="0.6 0.6 0.6 1.0" />
            </material>
        </visual>
        <!-- Collision: use same simple primitives -->
        <collision>
            <origin rpy="0 0 0" xyz="0 0 0" />
            <geometry>
                <cylinder length="0.10" radius="0.01" />
            </geometry>
        </collision>
    </link>
    <link name="rounded_tip">
        <inertial>
            <origin rpy="0 0 0" xyz="0 0 0.055" />
            <mass value="0.1" />
            <inertia ixx="1e-4" ixy="0" ixz="0" iyy="1e-4" iyz="0" izz="1e-4" />
        </inertial>
        <!-- Visual: sphere at the cylinder tip -->
        <visual>
            <!-- Sphere center at end of cylinder: z = length/2 + radius = 0.05 + 0.01 -->
            <origin rpy="0 0 0" xyz="0 0 0.055" />
            <geometry>
                <sphere radius="0.01" />
            </geometry>
            <material name="gray" />
        </visual>
        <collision>
            <origin rpy="0 0 0" xyz="0 0 0.055" />
            <geometry>
                <sphere radius="0.01" />
            </geometry>
        </collision>
    </link>
    <joint name="cone_tip_to_sphere" type="fixed">
        <parent link="rounded_tip_link" />
        <child link="rounded_tip" />
        <origin rpy="0 0 0" xyz="0 0 0" />
    </joint>
    <joint name="shoulder_lift_joint" type="revolute">
        <parent link="shoulder_link" />
        <child link="upper_arm_link" />
        <origin rpy="0.0 1.5707963267948966 0.0" xyz="0.0 0.220941 0.0" />
        <axis xyz="0 1 0" />
        <limit effort="330.0" lower="-3.1" upper="3.1" velocity="2.16" />
        <dynamics damping="0.0" friction="0.0" />
    </joint>
    <link name="upper_arm_link">
        <visual>
            <geometry>
                <mesh filename="package://ur_description/meshes/ur10/visual/upperarm.dae" />
            </geometry>
        </visual>
        <collision>
            <origin rpy="0 0 0" xyz="0 -0.05 0.3" />
            <geometry>
                <cylinder length="0.6" radius="0.11" />
            </geometry>
        </collision>
        <collision>
            <origin rpy="0 0 0" xyz="0 -0.05 0" />
            <geometry>
                <sphere radius="0.11" />
            </geometry>
        </collision>
        <collision>
            <origin rpy="0 0 0" xyz="0 -0.05 0.6" />
            <geometry>
                <sphere radius="0.11" />
            </geometry>
        </collision>
        <inertial>
            <mass value="12.93" />
            <origin rpy="0 0 0" xyz="0.0 0.0 0.306" />
            <inertia ixx="0.42175380379841093" ixy="0.0" ixz="0.0" iyy="0.42175380379841093" iyz="0.0" izz="0.03636562499999999" />
        </inertial>
    </link>
    <joint name="elbow_joint" type="revolute">
        <parent link="upper_arm_link" />
        <child link="forearm_link" />
        <origin rpy="0.0 0.0 0.0" xyz="0.0 -0.1719 0.612" />
        <axis xyz="0 1 0" />
        <limit effort="150.0" lower="-3.1" upper="3.1" velocity="3.15" />
        <dynamics damping="0.0" friction="0.0" />
    </joint>
    <link name="forearm_link">
        <visual>
            <geometry>
                <mesh filename="package://ur_description/meshes/ur10/visual/forearm.dae" />
            </geometry>
        </visual>
        <collision>
            <origin rpy="0 0 0" xyz="0 0 0.28" />
            <geometry>
                <cylinder length="0.56" radius="0.08" />
            </geometry>
        </collision>
        <collision>
            <origin rpy="0 0 0" xyz="0 0 0.56" />
            <geometry>
                <sphere radius="0.08" />
            </geometry>
        </collision>
        <collision>
            <origin rpy="0 0 0" xyz="0 0 0" />
            <geometry>
                <sphere radius="0.08" />
            </geometry>
        </collision>
        <inertial>
            <mass value="3.87" />
            <origin rpy="0 0 0" xyz="0.0 0.0 0.28615" />
            <inertia ixx="0.11106969409710458" ixy="0.0" ixz="0.0" iyy="0.11106969409710458" iyz="0.0" izz="0.010884375" />
        </inertial>
    </link>
    <joint name="wrist_1_joint" type="revolute">
        <parent link="forearm_link" />
        <child link="wrist_1_link" />
        <origin rpy="0.0 1.5707963267948966 0.0" xyz="0.0 0.0 0.5723" />
        <axis xyz="0 1 0" />
        <limit effort="54.0" lower="-3.1" upper="3.1" velocity="3.2" />
        <dynamics damping="0.0" friction="0.0" />
    </joint>
    <link name="wrist_1_link">
        <visual>
            <geometry>
                <mesh filename="package://ur_description/meshes/ur10/visual/wrist1.dae" />
            </geometry>
        </visual>
        <collision>
            <origin rpy="0 0 0" xyz="0 0.1149 0" />
            <geometry>
                <sphere radius="0.07" />
            </geometry>
        </collision>
        <inertial>
            <mass value="1.96" />
            <origin rpy="0 0 0" xyz="0.0 0.0 0.0" />
            <inertia ixx="0.005108247956699999" ixy="0.0" ixz="0.0" iyy="0.005108247956699999" iyz="0.0" izz="0.005512499999999999" />
        </inertial>
    </link>
    <joint name="wrist_2_joint" type="revolute">
        <parent link="wrist_1_link" />
        <child link="wrist_2_link" />
        <origin rpy="0.0 0.0 0.0" xyz="0.0 0.1149 0.0" />
        <axis xyz="0 0 1" />
        <limit effort="54.0" lower="-3.1" upper="3.1" velocity="3.2" />
        <dynamics damping="0.0" friction="0.0" />
    </joint>
    <link name="wrist_2_link">
        <visual>
            <geometry>
                <mesh filename="package://ur_description/meshes/ur10/visual/wrist2.dae" />
            </geometry>
        </visual>
        <collision>
            <origin rpy="-1.5707963267948966 0 0" xyz="0 0.0 0.1157" />
            <geometry>
                <cylinder length="0.08" radius="0.05" />
            </geometry>
        </collision>
        <collision>
            <origin rpy="0 0 0" xyz="0 -0.04 0.1157" />
            <geometry>
                <sphere radius="0.05" />
            </geometry>
        </collision>
        <collision>
            <origin rpy="0 0 0" xyz="0 0.04 0.1157" />
            <geometry>
                <sphere radius="0.05" />
            </geometry>
        </collision>
        <inertial>
            <mass value="1.96" />
            <origin rpy="0 0 0" xyz="0.0 0.0 0.0" />
            <inertia ixx="0.005108247956699999" ixy="0.0" ixz="0.0" iyy="0.005108247956699999" iyz="0.0" izz="0.005512499999999999" />
        </inertial>
    </link>
    <joint name="wrist_3_joint" type="revolute">
        <parent link="wrist_2_link" />
        <child link="wrist_3_link" />
        <origin rpy="0.0 0.0 0.0" xyz="0.0 0.0 0.1157" />
        <axis xyz="0 1 0" />
        <limit effort="54.0" lower="-3.1" upper="3.1" velocity="3.2" />
        <dynamics damping="0.0" friction="0.0" />
    </joint>
    <link name="wrist_3_link">
        <visual>
            <geometry>
                <mesh filename="package://ur_description/meshes/ur10/visual/wrist3.dae" />
            </geometry>
        </visual>
        <collision>
            <origin rpy="0 0 0" xyz="0 0.1 0" />
            <geometry>
                <sphere radius="0.05" />
            </geometry>
        </collision>
        <inertial>
            <mass value="0.202" />
            <origin rpy="0 0 0" xyz="0.0 0.0 0.0" />
            <inertia ixx="0.000526462289415" ixy="0.0" ixz="0.0" iyy="0.000526462289415" iyz="0.0" izz="0.0005681249999999999" />
        </inertial>
    </link>
    <joint name="ee_fixed_joint" type="fixed">
        <parent link="wrist_3_link" />
        <child link="ee_link" />
        <origin rpy="0.0 0.0 1.5707963267948966" xyz="0.0 0.0922 0.0" />
    </joint>
    <link name="ee_link" />
    <joint name="my_eff" type="fixed">
        <parent link="ee_link" />
        <child link="rounded_tip_link" />
        <origin rpy="0 1.57 0" xyz="0 0 0" />
    </joint>
    <transmission name="shoulder_pan_trans">
        <type>transmission_interface/SimpleTransmission</type>
        <joint name="shoulder_pan_joint">
            <hardwareInterface>hardware_interface/VelocityJointInterface</hardwareInterface>
        </joint>
        <actuator name="shoulder_pan_motor">
            <mechanicalReduction>1</mechanicalReduction>
            <hardwareInterface>hardware_interface/VelocityJointInterface</hardwareInterface>
        </actuator>
    </transmission>
    <transmission name="shoulder_lift_trans">
        <type>transmission_interface/SimpleTransmission</type>
        <joint name="shoulder_lift_joint">
            <hardwareInterface>hardware_interface/VelocityJointInterface</hardwareInterface>
        </joint>
        <actuator name="shoulder_lift_motor">
            <mechanicalReduction>1</mechanicalReduction>
            <hardwareInterface>hardware_interface/VelocityJointInterface</hardwareInterface>
        </actuator>
    </transmission>
    <transmission name="elbow_trans">
        <type>transmission_interface/SimpleTransmission</type>
        <joint name="elbow_joint">
            <hardwareInterface>hardware_interface/VelocityJointInterface</hardwareInterface>
        </joint>
        <actuator name="elbow_motor">
            <mechanicalReduction>1</mechanicalReduction>
            <hardwareInterface>hardware_interface/VelocityJointInterface</hardwareInterface>
        </actuator>
    </transmission>
    <transmission name="wrist_1_trans">
        <type>transmission_interface/SimpleTransmission</type>
        <joint name="wrist_1_joint">
            <hardwareInterface>hardware_interface/VelocityJointInterface</hardwareInterface>
        </joint>
        <actuator name="wrist_1_motor">
            <mechanicalReduction>1</mechanicalReduction>
            <hardwareInterface>hardware_interface/VelocityJointInterface</hardwareInterface>
        </actuator>
    </transmission>
    <transmission name="wrist_2_trans">
        <type>transmission_interface/SimpleTransmission</type>
        <joint name="wrist_2_joint">
            <hardwareInterface>hardware_interface/VelocityJointInterface</hardwareInterface>
        </joint>
        <actuator name="wrist_2_motor">
            <mechanicalReduction>1</mechanicalReduction>
            <hardwareInterface>hardware_interface/VelocityJointInterface</hardwareInterface>
        </actuator>
    </transmission>
    <transmission name="wrist_3_trans">
        <type>transmission_interface/SimpleTransmission</type>
        <joint name="wrist_3_joint">
            <hardwareInterface>hardware_interface/VelocityJointInterface</hardwareInterface>
        </joint>
        <actuator name="wrist_3_motor">
            <mechanicalReduction>1</mechanicalReduction>
            <hardwareInterface>hardware_interface/VelocityJointInterface</hardwareInterface>
        </actuator>
    </transmission>
    <!-- without 3d camera end -->
    <link name="pedestal_link">
        <visual>
            <origin rpy="0.0 0.0 0.0" xyz="-0.23 -0.33 -0.013" />
            <geometry>
                <mesh filename="package://ur_description/meshes/rst_ft/rst_base.stl" scale="0.0255 0.0255 0.0253" />
            </geometry>
            <!-- Error loading color after going to Noetic: added <.color> -->
            <material name="dark_grey">
                <color rgba="0.2 0.2 0.2 1.0" />
                <!-- Dark grey color with alpha = 1.0 -->
            </material>
        </visual>
        <collision>
            <origin rpy="0 0 0" xyz="0 0 0.38" />
            <geometry>
                <cylinder length="0.76" radius="0.1" />
            </geometry>
        </collision>
        <collision>
            <origin rpy="0 0 0" xyz="0 0 0.76" />
            <geometry>
                <sphere radius="0.1" />
            </geometry>
        </collision>
        <inertial>
            <mass value="0.1" />
            <origin xyz="0 0 0" rpy="0 0 0" />
            <inertia ixx="0.03" iyy="0.03" izz="0.03" ixy="0.0" ixz="0.0" iyz="0.0" />
        </inertial>
    </link>
    <joint name="mount" type="fixed">
        <origin rpy="0 0 0" xyz="0.0 0.0 0.8" />
        <parent link="pedestal_link" />
        <child link="base_link" />
    </joint>
    <link name="world" />
    <link name="ground" />
    <link name="roof" />
    <joint name="world_joint" type="fixed">
        <parent link="world" />
        <child link="pedestal_link" />
        <origin rpy="0.0 0.0 0.0" xyz="0.0 0.0 0.0" />
    </joint>
    <joint name="ground_joint" type="fixed">
        <parent link="world" />
        <child link="ground" />
        <origin rpy="0.0 0.0 0.0" xyz="0.0 0.0 0.0" />
    </joint>
    <joint name="roof_joint" type="fixed">
        <parent link="world" />
        <child link="roof" />
        <origin rpy="3.14 0.0 0.0" xyz="0.0 0.0 2.5" />
    </joint>
    <gazebo reference="pedestal_link">
        <turnGravityOff>1</turnGravityOff>
        <plugin name="gazebo_ros_control" filename="libgazebo_ros_control.so">
            <robotNamespace>/</robotNamespace>
        </plugin>
    </gazebo>
    <gazebo reference="base_link">
        <turnGravityOff>1</turnGravityOff>
    </gazebo>
    <gazebo reference="shoulder_link">
        <turnGravityOff>1</turnGravityOff>
    </gazebo>
    <gazebo reference="upper_arm_link">
        <turnGravityOff>1</turnGravityOff>
    </gazebo>
    <gazebo reference="forearm_link">
        <turnGravityOff>1</turnGravityOff>
    </gazebo>
    <gazebo reference="wrist_1_link">
        <turnGravityOff>1</turnGravityOff>
    </gazebo>
    <gazebo reference="wrist_2_link">
        <turnGravityOff>1</turnGravityOff>
    </gazebo>
    <gazebo reference="wrist_3_link">
        <turnGravityOff>1</turnGravityOff>
    </gazebo>
    <gazebo reference="ee_link">
        <turnGravityOff>1</turnGravityOff>
    </gazebo>
    <gazebo>
        <plugin filename="libgazebo_ros_control.so" name="gazebo_ros_control">
            <robotNamespace>/ur10</robotNamespace>
            <legacyModeNS>true</legacyModeNS>
        </plugin>
    </gazebo>
</robot>

